Workbook

Sheet CurrentModel
A1: https://iopscience.iop.org/0004-637X/761/2/166/suppdata/apj450768t1_mrt.txt
A2: FROM HU, SEAGER, BAINS 2012 TABLE 1+2+Reaction_X Files | H2: LATER ADDITIONS | K2: Zone_Scenario | S2: From Reaction_X.txt
A3: Reaction Label | B3: Reactants | C3: Products | D3: Rate Law | E3: Source | F3: Valid Temperature Range | G3: Notes | H3: Detailed References | I3: Rate Selection Notes | J3: Comparison to Other Networks/Models | K3: Earth_Full | L3: Mars | M3: Exoplanet_noN | N3: CO2N2r | O3: N2r | P3: H2r1 | Q3: Exoplanet_Full | S3: Numerical Reactants | U3: Numerical Products | X3: Named Reactants | Z3: Named Products | AC3: Correct? | AD3: Checked?
A4: P1 | B4: O2 | C4: O + O | K4: X | L4: X | M4: X | N4: X | O4: X | P4: X | Q4: X | S4: 54 | T4: 0 | U4: 1 | V4: 1 | W4: 0 | X4: =INDEX(SpeciesName!$A$2:$B$113, CurrentModel!S4+1,2) -> O2 | Y4: =INDEX(SpeciesName!$A$2:$B$113, CurrentModel!T4+1,2) -> - | Z4: =INDEX(SpeciesName!$A$2:$B$113, CurrentModel!U4+1,2) -> O | AA4: =INDEX(SpeciesName!$A$2:$B$113, CurrentModel!V4+1,2) -> O | AB4: =INDEX(SpeciesName!$A$2:$B$113, CurrentModel!W4+1,2) -> - | AC4: Yes | AD4: SR 1/11/24
A5: P2 | B5: O2 | C5: O + O(1D) | K5: X | L5: X | M5: X | N5: X | O5: X | P5: X | Q5: X | X5: =INDEX(SpeciesName!$A$2:$B$113, CurrentModel!S5+1,2) -> - | Y5: =INDEX(SpeciesName!$A$2:$B$113, CurrentModel!T5+1,2) -> - | Z5: =INDEX(SpeciesName!$A$2:$B$113, CurrentModel!U5+1,2) -> - | AA5: =INDEX(SpeciesName!$A$2:$B$113, CurrentModel!V5+1,2) -> - | AB5: =INDEX(SpeciesName!$A$2:$B$113, CurrentModel!W5+1,2) -> -
A6: P3 | B6: O3 | C6: O2 + O | K6: X | L6: X | M6: X | N6: X | O6: X | P6: X | Q6: X | X6: =INDEX(SpeciesName!$A$2:$B$113, CurrentModel!S6+1,2) -> - | Y6: =INDEX(SpeciesName!$A$2:$B$113, CurrentModel!T6+1,2) -> - | Z6: =INDEX(SpeciesName!$A$2:$B$113, CurrentModel!U6+1,2) -> - | AA6: =INDEX(SpeciesName!$A$2:$B$113, CurrentModel!V6+1,2) -> - | AB6: =INDEX(SpeciesName!$A$2:$B$113, CurrentModel!W6+1,2) -> -
A7: P4 | B7: O3 | C7: O2 + O(1D) | K7: X | L7: X | M7: X | N7: X | O7: X | P7: X | Q7: X | X7: =INDEX(SpeciesName!$A$2:$B$113, CurrentModel!S7+1,2) -> - | Y7: =INDEX(SpeciesName!$A$2:$B$113, CurrentModel!T7+1,2) -> - | Z7: =INDEX(SpeciesName!$A$2:$B$113, CurrentModel!U7+1,2) -> - | AA7: =INDEX(SpeciesName!$A$2:$B$113, CurrentModel!V7+1,2) -> - | AB7: =INDEX(SpeciesName!$A$2:$B$113, CurrentModel!W7+1,2) -> -
A8: P5 | B8: HO2 | C8: O + OH | K8: X | L8: X | M8: X | N8: X | O8: X | P8: X | Q8: X | X8: =INDEX(SpeciesName!$A$2:$B$113, CurrentModel!S8+1,2) -> - | Y8: =INDEX(SpeciesName!$A$2:$B$113, CurrentModel!T8+1,2) -> - | Z8: =INDEX(SpeciesName!$A$2:$B$113, CurrentModel!U8+1,2) -> - | AA8: =INDEX(SpeciesName!$A$2:$B$113, CurrentModel!V8+1,2) -> - | AB8: =INDEX(SpeciesName!$A$2:$B$113, CurrentModel!W8+1,2) -> -
A9: P6 | B9: H2O | C9: H + OH | K9: X | L9: X | M9: X | N9: X | O9: X | P9: X | Q9: X | X9: =INDEX(SpeciesName!$A$2:$B$113, CurrentModel!S9+1,2) -> - | Y9: =INDEX(SpeciesName!$A$2:$B$113, CurrentModel!T9+1,2) -> - | Z9: =INDEX(SpeciesName!$A$2:$B$113, CurrentModel!U9+1,2) -> - | AA9: =INDEX(SpeciesName!$A$2:$B$113, CurrentModel!V9+1,2) -> - | AB9: =INDEX(SpeciesName!$A$2:$B$113, CurrentModel!W9+1,2) -> -
A10: P7 | B10: H2O2 | C10: OH + OH | K10: X | L10: X | M10: X | N10: X | O10: X | P10: X | Q10: X | X10: =INDEX(SpeciesName!$A$2:$B$113, CurrentModel!S10+1,2) -> - | Y10: =INDEX(SpeciesName!$A$2:$B$113, CurrentModel!T10+1,2) -> - | Z10: =INDEX(SpeciesName!$A$2:$B$113, CurrentModel!U10+1,2) -> - | AA10: =INDEX(SpeciesName!$A$2:$B$113, CurrentModel!V10+1,2) -> - | AB10: =INDEX(SpeciesName!$A$2:$B$113, CurrentModel!W10+1,2) -> -
A11: P8 | B11: NO2 | C11: NO + O | K11: X | L11: X | Q11: X | X11: =INDEX(SpeciesName!$A$2:$B$113, CurrentModel!S11+1,2) -> - | Y11: =INDEX(SpeciesName!$A$2:$B$113, CurrentModel!T11+1,2) -> - | Z11: =INDEX(SpeciesName!$A$2:$B$113, CurrentModel!U11+1,2) -> - | AA11: =INDEX(SpeciesName!$A$2:$B$113, CurrentModel!V11+1,2) -> - | AB11: =INDEX(SpeciesName!$A$2:$B$113, CurrentModel!W11+1,2) -> -
A12: P9 | B12: NO3 | C12: NO + O2 | K12: X | L12: X | Q12: X | X12: =INDEX(SpeciesName!$A$2:$B$113, CurrentModel!S12+1,2) -> - | Y12: =INDEX(SpeciesName!$A$2:$B$113, CurrentModel!T12+1,2) -> - | Z12: =INDEX(SpeciesName!$A$2:$B$113, CurrentModel!U12+1,2) -> - | AA12: =INDEX(SpeciesName!$A$2:$B$113, CurrentModel!V12+1,2) -> - | AB12: =INDEX(SpeciesName!$A$2:$B$113, CurrentModel!W12+1,2) -> -
A13: P10 | B13: NO3 | C13: NO2 + O | K13: X | L13: X | Q13: X | X13: =INDEX(SpeciesName!$A$2:$B$113, CurrentModel!S13+1,2) -> - | Y13: =INDEX(SpeciesName!$A$2:$B$113, CurrentModel!T13+1,2) -> - | Z13: =INDEX(SpeciesName!$A$2:$B$113, CurrentModel!U13+1,2) -> - | AA13: =INDEX(SpeciesName!$A$2:$B$113, CurrentModel!V13+1,2) -> - | AB13: =INDEX(SpeciesName!$A$2:$B$113, CurrentModel!W13+1,2) -> -
A14: P11 | B14: N2O | C14: N2 + O(1D) | K14: X | L14: X | Q14: X | X14: =INDEX(SpeciesName!$A$2:$B$113, CurrentModel!S14+1,2) -> - | Y14: =INDEX(SpeciesName!$A$2:$B$113, CurrentModel!T14+1,2) -> - | Z14: =INDEX(SpeciesName!$A$2:$B$113, CurrentModel!U14+1,2) -> - | AA14: =INDEX(SpeciesName!$A$2:$B$113, CurrentModel!V14+1,2) -> - | AB14: =INDEX(SpeciesName!$A$2:$B$113, CurrentModel!W14+1,2) -> -
A15: P12 | B15: N2O5 | C15: NO3 + NO2 | K15: X | L15: X | Q15: X | X15: =INDEX(SpeciesName!$A$2:$B$113, CurrentModel!S15+1,2) -> - | Y15: =INDEX(SpeciesName!$A$2:$B$113, CurrentModel!T15+1,2) -> - | Z15: =INDEX(SpeciesName!$A$2:$B$113, CurrentModel!U15+1,2) -> - | AA15: =INDEX(SpeciesName!$A$2:$B$113, CurrentModel!V15+1,2) -> - | AB15: =INDEX(SpeciesName!$A$2:$B$113, CurrentModel!W15+1,2) -> -
A16: P13 | B16: N2O5 | C16: NO3 + NO + O | K16: X | L16: X | Q16: X | X16: =INDEX(SpeciesName!$A$2:$B$113, CurrentModel!S16+1,2) -> - | Y16: =INDEX(SpeciesName!$A$2:$B$113, CurrentModel!T16+1,2) -> - | Z16: =INDEX(SpeciesName!$A$2:$B$113, CurrentModel!U16+1,2) -> - | AA16: =INDEX(SpeciesName!$A$2:$B$113, CurrentModel!V16+1,2) -> - | AB16: =INDEX(SpeciesName!$A$2:$B$113, CurrentModel!W16+1,2) -> -
A17: P14 | B17: HNO2 | C17: NO + OH | K17: X | L17: X | Q17: X | X17: =INDEX(SpeciesName!$A$2:$B$113, CurrentModel!S17+1,2) -> - | Y17: =INDEX(SpeciesName!$A$2:$B$113, CurrentModel!T17+1,2) -> - | Z17: =INDEX(SpeciesName!$A$2:$B$113, CurrentModel!U17+1,2) -> - | AA17: =INDEX(SpeciesName!$A$2:$B$113, CurrentModel!V17+1,2) -> - | AB17: =INDEX(SpeciesName!$A$2:$B$113, CurrentModel!W17+1,2) -> -
A18: P15 | B18: HNO3 | C18: NO2 + OH | K18: X | L18: X | Q18: X | X18: =INDEX(SpeciesName!$A$2:$B$113, CurrentModel!S18+1,2) -> - | Y18: =INDEX(SpeciesName!$A$2:$B$113, CurrentModel!T18+1,2) -> - | Z18: =INDEX(SpeciesName!$A$2:$B$113, CurrentModel!U18+1,2) -> - | AA18: =INDEX(SpeciesName!$A$2:$B$113, CurrentModel!V18+1,2) -> - | AB18: =INDEX(SpeciesName!$A$2:$B$113, CurrentModel!W18+1,2) -> -
A19: P16 | B19: HNO3 | C19: HNO2 + O | K19: X | L19: X | Q19: X | X19: =INDEX(SpeciesName!$A$2:$B$113, CurrentModel!S19+1,2) -> - | Y19: =INDEX(SpeciesName!$A$2:$B$113, CurrentModel!T19+1,2) -> - | Z19: =INDEX(SpeciesName!$A$2:$B$113, CurrentModel!U19+1,2) -> - | AA19: =INDEX(SpeciesName!$A$2:$B$113, CurrentModel!V19+1,2) -> - | AB19: =INDEX(SpeciesName!$A$2:$B$113, CurrentModel!W19+1,2) -> -
A20: P17 | B20: HNO3 | C20: HNO2 + O(1D) | K20: X | L20: X | Q20: X | X20: =INDEX(SpeciesName!$A$2:$B$113, CurrentModel!S20+1,2) -> - | Y20: =INDEX(SpeciesName!$A$2:$B$113, CurrentModel!T20+1,2) -> - | Z20: =INDEX(SpeciesName!$A$2:$B$113, CurrentModel!U20+1,2) -> - | AA20: =INDEX(SpeciesName!$A$2:$B$113, CurrentModel!V20+1,2) -> - | AB20: =INDEX(SpeciesName!$A$2:$B$113, CurrentModel!W20+1,2) -> -
A21: P18 | B21: HNO4 | C21: NO2 + HO2 | K21: X | L21: X | Q21: X | X21: =INDEX(SpeciesName!$A$2:$B$113, CurrentModel!S21+1,2) -> - | Y21: =INDEX(SpeciesName!$A$2:$B$113, CurrentModel!T21+1,2) -> - | Z21: =INDEX(SpeciesName!$A$2:$B$113, CurrentModel!U21+1,2) -> - | AA21: =INDEX(SpeciesName!$A$2:$B$113, CurrentModel!V21+1,2) -> - | AB21: =INDEX(SpeciesName!$A$2:$B$113, CurrentModel!W21+1,2) -> -
A22: P19 | B22: HNO4 | C22: NO3 + OH | K22: X | L22: X | Q22: X | X22: =INDEX(SpeciesName!$A$2:$B$113, CurrentModel!S22+1,2) -> - | Y22: =INDEX(SpeciesName!$A$2:$B$113, CurrentModel!T22+1,2) -> - | Z22: =INDEX(SpeciesName!$A$2:$B$113, CurrentModel!U22+1,2) -> - | AA22: =INDEX(SpeciesName!$A$2:$B$113, CurrentModel!V22+1,2) -> - | AB22: =INDEX(SpeciesName!$A$2:$B$113, CurrentModel!W22+1,2) -> -
A23: P20 | B23: CH2O | C23: CHO + H | K23: X | L23: X | M23: X | N23: X | O23: X | P23: X | Q23: X | X23: =INDEX(SpeciesName!$A$2:$B$113, CurrentModel!S23+1,2) -> - | Y23: =INDEX(SpeciesName!$A$2:$B$113, CurrentModel!T23+1,2) -> - | Z23: =INDEX(SpeciesName!$A$2:$B$113, CurrentModel!U23+1,2) -> - | AA23: =INDEX(SpeciesName!$A$2:$B$113, CurrentModel!V23+1,2) -> - | AB23: =INDEX(SpeciesName!$A$2:$B$113, CurrentModel!W23+1,2) -> -
A24: P21 | B24: CH2O | C24: CO + H2 | K24: X | L24: X | M24: X | N24: X | O24: X | P24: X | Q24: X | X24: =INDEX(SpeciesName!$A$2:$B$113, CurrentModel!S24+1,2) -> - | Y24: =INDEX(SpeciesName!$A$2:$B$113, CurrentModel!T24+1,2) -> - | Z24: =INDEX(SpeciesName!$A$2:$B$113, CurrentModel!U24+1,2) -> - | AA24: =INDEX(SpeciesName!$A$2:$B$113, CurrentModel!V24+1,2) -> - | AB24: =INDEX(SpeciesName!$A$2:$B$113, CurrentModel!W24+1,2) -> -
A25: P22 | B25: C2H4O | C25: CHO + CH4 | K25: X | L25: X | M25: X | N25: X | O25: X | P25: X | Q25: X | X25: =INDEX(SpeciesName!$A$2:$B$113, CurrentModel!S25+1,2) -> - | Y25: =INDEX(SpeciesName!$A$2:$B$113, CurrentModel!T25+1,2) -> - | Z25: =INDEX(SpeciesName!$A$2:$B$113, CurrentModel!U25+1,2) -> - | AA25: =INDEX(SpeciesName!$A$2:$B$113, CurrentModel!V25+1,2) -> - | AB25: =INDEX(SpeciesName!$A$2:$B$113, CurrentModel!W25+1,2) -> -
A26: P23 | B26: C2H4O | C26: CO + CH4 | K26: X | L26: X | M26: X | N26: X | O26: X | P26: X | Q26: X | X26: =INDEX(SpeciesName!$A$2:$B$113, CurrentModel!S26+1,2) -> - | Y26: =INDEX(SpeciesName!$A$2:$B$113, CurrentModel!T26+1,2) -> - | Z26: =INDEX(SpeciesName!$A$2:$B$113, CurrentModel!U26+1,2) -> - | AA26: =INDEX(SpeciesName!$A$2:$B$113, CurrentModel!V26+1,2) -> - | AB26: =INDEX(SpeciesName!$A$2:$B$113, CurrentModel!W26+1,2) -> -
A27: P24 | B27: CH4O2 | C27: CH3O + OH | K27: X | L27: X | M27: X | N27: X | O27: X | P27: X | Q27: X | X27: =INDEX(SpeciesName!$A$2:$B$113, CurrentModel!S27+1,2) -> - | Y27: =INDEX(SpeciesName!$A$2:$B$113, CurrentModel!T27+1,2) -> - | Z27: =INDEX(SpeciesName!$A$2:$B$113, CurrentModel!U27+1,2) -> - | AA27: =INDEX(SpeciesName!$A$2:$B$113, CurrentModel!V27+1,2) -> - | AB27: =INDEX(SpeciesName!$A$2:$B$113, CurrentModel!W27+1,2) -> -
A28: P25 | B28: CH3NO2 | C28: CH3O + NO | K28: X | L28: X | Q28: X | X28: =INDEX(SpeciesName!$A$2:$B$113, CurrentModel!S28+1,2) -> - | Y28: =INDEX(SpeciesName!$A$2:$B$113, CurrentModel!T28+1,2) -> - | Z28: =INDEX(SpeciesName!$A$2:$B$113, CurrentModel!U28+1,2) -> - | AA28: =INDEX(SpeciesName!$A$2:$B$113, CurrentModel!V28+1,2) -> - | AB28: =INDEX(SpeciesName!$A$2:$B$113, CurrentModel!W28+1,2) -> -
A29: P26 | B29: CH3NO3 | C29: CH3O + NO2 | K29: X | L29: X | Q29: X | X29: =INDEX(SpeciesName!$A$2:$B$113, CurrentModel!S29+1,2) -> - | Y29: =INDEX(SpeciesName!$A$2:$B$113, CurrentModel!T29+1,2) -> - | Z29: =INDEX(SpeciesName!$A$2:$B$113, CurrentModel!U29+1,2) -> - | AA29: =INDEX(SpeciesName!$A$2:$B$113, CurrentModel!V29+1,2) -> - | AB29: =INDEX(SpeciesName!$A$2:$B$113, CurrentModel!W29+1,2) -> -
A30: P27 | B30: CH2O2 | C30: CHO + OH | K30: X | L30: X | M30: X | N30: X | O30: X | P30: X | Q30: X | X30: =INDEX(SpeciesName!$A$2:$B$113, CurrentModel!S30+1,2) -> - | Y30: =INDEX(SpeciesName!$A$2:$B$113, CurrentModel!T30+1,2) -> - | Z30: =INDEX(SpeciesName!$A$2:$B$113, CurrentModel!U30+1,2) -> - | AA30: =INDEX(SpeciesName!$A$2:$B$113, CurrentModel!V30+1,2) -> - | AB30: =INDEX(SpeciesName!$A$2:$B$113, CurrentModel!W30+1,2) -> -
A31: P28 | B31: CH2O2 | C31: CHO2 + H | K31: X | L31: X | M31: X | N31: X | O31: X | Q31: X | S31: 23 | T31: 0 | U31: 63 | V31: 3 | W31: 0 | X31: =INDEX(SpeciesName!$A$2:$B$113, CurrentModel!S31+1,2) -> CH2O2 | Y31: =INDEX(SpeciesName!$A$2:$B$113, CurrentModel!T31+1,2) -> - | Z31: =INDEX(SpeciesName!$A$2:$B$113, CurrentModel!U31+1,2) -> CHO2 | AA31: =INDEX(SpeciesName!$A$2:$B$113, CurrentModel!V31+1,2) -> H | AB31: =INDEX(SpeciesName!$A$2:$B$113, CurrentModel!W31+1,2) -> - | AC31: Yes | AD31: SR 1/18/24
A32: P29 | B32: CH2O2 | C32: H2O + CO | K32: X | L32: X | M32: X | N32: X | O32: X | P32: X | Q32: X | X32: =INDEX(SpeciesName!$A$2:$B$113, CurrentModel!S32+1,2) -> - | Y32: =INDEX(SpeciesName!$A$2:$B$113, CurrentModel!T32+1,2) -> - | Z32: =INDEX(SpeciesName!$A$2:$B$113, CurrentModel!U32+1,2) -> - | AA32: =INDEX(SpeciesName!$A$2:$B$113, CurrentModel!V32+1,2) -> - | AB32: =INDEX(SpeciesName!$A$2:$B$113, CurrentModel!W32+1,2) -> -
A33: P30 | B33: SO3 | C33: SO2 + O | K33: X | M33: X | N33: X | O33: X | P33: X | Q33: X | X33: =INDEX(SpeciesName!$A$2:$B$113, CurrentModel!S33+1,2) -> - | Y33: =INDEX(SpeciesName!$A$2:$B$113, CurrentModel!T33+1,2) -> - | Z33: =INDEX(SpeciesName!$A$2:$B$113, CurrentModel!U33+1,2) -> - | AA33: =INDEX(SpeciesName!$A$2:$B$113, CurrentModel!V33+1,2) -> - | AB33: =INDEX(SpeciesName!$A$2:$B$113, CurrentModel!W33+1,2) -> -
A34: P31 | B34: OCS | C34: CO + S | K34: X | Q34: X | X34: =INDEX(SpeciesName!$A$2:$B$113, CurrentModel!S34+1,2) -> - | Y34: =INDEX(SpeciesName!$A$2:$B$113, CurrentModel!T34+1,2) -> - | Z34: =INDEX(SpeciesName!$A$2:$B$113, CurrentModel!U34+1,2) -> - | AA34: =INDEX(SpeciesName!$A$2:$B$113, CurrentModel!V34+1,2) -> - | AB34: =INDEX(SpeciesName!$A$2:$B$113, CurrentModel!W34+1,2) -> -
A35: P32 | B35: CH4 | C35: CH3 + H | K35: X | L35: X | M35: X | N35: X | O35: X | P35: X | Q35: X | X35: =INDEX(SpeciesName!$A$2:$B$113, CurrentModel!S35+1,2) -> - | Y35: =INDEX(SpeciesName!$A$2:$B$113, CurrentModel!T35+1,2) -> - | Z35: =INDEX(SpeciesName!$A$2:$B$113, CurrentModel!U35+1,2) -> - | AA35: =INDEX(SpeciesName!$A$2:$B$113, CurrentModel!V35+1,2) -> - | AB35: =INDEX(SpeciesName!$A$2:$B$113, CurrentModel!W35+1,2) -> -
A36: P33 | B36: CH4 | C36: CH2(1) + H2 | K36: X | L36: X | M36: X | N36: X | O36: X | P36: X | Q36: X | X36: =INDEX(SpeciesName!$A$2:$B$113, CurrentModel!S36+1,2) -> - | Y36: =INDEX(SpeciesName!$A$2:$B$113, CurrentModel!T36+1,2) -> - | Z36: =INDEX(SpeciesName!$A$2:$B$113, CurrentModel!U36+1,2) -> - | AA36: =INDEX(SpeciesName!$A$2:$B$113, CurrentModel!V36+1,2) -> - | AB36: =INDEX(SpeciesName!$A$2:$B$113, CurrentModel!W36+1,2) -> -
A37: P34 | B37: CH4 | C37: CH + H2 + H | K37: X | L37: X | M37: X | N37: X | O37: X | P37: X | Q37: X | X37: =INDEX(SpeciesName!$A$2:$B$113, CurrentModel!S37+1,2) -> - | Y37: =INDEX(SpeciesName!$A$2:$B$113, CurrentModel!T37+1,2) -> - | Z37: =INDEX(SpeciesName!$A$2:$B$113, CurrentModel!U37+1,2) -> - | AA37: =INDEX(SpeciesName!$A$2:$B$113, CurrentModel!V37+1,2) -> - | AB37: =INDEX(SpeciesName!$A$2:$B$113, CurrentModel!W37+1,2) -> -
A38: P35 | B38: CO | C38: C + O | K38: X | L38: X | M38: X | N38: X | O38: X | P38: X | Q38: X | X38: =INDEX(SpeciesName!$A$2:$B$113, CurrentModel!S38+1,2) -> - | Y38: =INDEX(SpeciesName!$A$2:$B$113, CurrentModel!T38+1,2) -> - | Z38: =INDEX(SpeciesName!$A$2:$B$113, CurrentModel!U38+1,2) -> - | AA38: =INDEX(SpeciesName!$A$2:$B$113, CurrentModel!V38+1,2) -> - | AB38: =INDEX(SpeciesName!$A$2:$B$113, CurrentModel!W38+1,2) -> -
A39: P36 | B39: CO2 | C39: CO + O | K39: X | L39: X | M39: X | N39: X | O39: X | P39: X | Q39: X | X39: =INDEX(SpeciesName!$A$2:$B$113, CurrentModel!S39+1,2) -> - | Y39: =INDEX(SpeciesName!$A$2:$B$113, CurrentModel!T39+1,2) -> - | Z39: =INDEX(SpeciesName!$A$2:$B$113, CurrentModel!U39+1,2) -> - | AA39: =INDEX(SpeciesName!$A$2:$B$113, CurrentModel!V39+1,2) -> - | AB39: =INDEX(SpeciesName!$A$2:$B$113, CurrentModel!W39+1,2) -> -
A40: P37 | B40: CO2 | C40: CO + O(1D) | K40: X | L40: X | M40: X | N40: X | O40: X | P40: X | Q40: X | X40: =INDEX(SpeciesName!$A$2:$B$113, CurrentModel!S40+1,2) -> - | Y40: =INDEX(SpeciesName!$A$2:$B$113, CurrentModel!T40+1,2) -> - | Z40: =INDEX(SpeciesName!$A$2:$B$113, CurrentModel!U40+1,2) -> - | AA40: =INDEX(SpeciesName!$A$2:$B$113, CurrentModel!V40+1,2) -> - | AB40: =INDEX(SpeciesName!$A$2:$B$113, CurrentModel!W40+1,2) -> -
...

Sheet SpeciesName
A1: No. | B1: Species Name
A2: 0 | B2: -
A3: 1 | B3: O
A4: 2 | B4: O3
A5: 3 | B5: H
A6: 4 | B6: OH
A7: 5 | B7: HO2
A8: 6 | B8: H2O2
A9: 7 | B9: H2O
A10: 8 | B10: N
A11: 9 | B11: NH3
A12: 10 | B12: NH2
A13: 11 | B13: N2O
... A113: 111 | B113: S8A
